<robot name = "robot">
    <link name="Torso">
        <inertial>
            <origin xyz="0 0 1" rpy="0 0 0"/>
            <mass value="1" />
            <inertia ixx="100" ixy="0" ixz="0" iyy="100" iyz="0" izz="100" />
        </inertial>
        <visual>
            <origin xyz="0 0 1" rpy="0 0 0"/>
            <geometry>
                <box size="1 1 1" />
            </geometry>
            <material name="Cyan">
                <color rgba="0 1.0 1.0 1.0"/>
            </material>
        </visual>
        <collision>
            <origin xyz="0 0 1" rpy="0 0 0"/>
            <geometry>
                <box size="1 1 1" />
            </geometry>
        </collision>
    </link>
    <joint name="Torso_FrontLeg" type="revolute">
       <parent link="Torso"/>
       <child  link="FrontLeg"/>
       <origin rpy="0 0 0" xyz="0 0.5 1" />
     <axis xyz="1 0 0"/>
       <limit effort="0.0" lower="-3.14159" upper="3.14159" velocity="0.0"/>
    </joint>
    <link name="FrontLeg">
        <inertial>
            <origin xyz="0 0.5 0" rpy="0 0 0"/>
            <mass value="1" />
            <inertia ixx="100" ixy="0" ixz="0" iyy="100" iyz="0" izz="100" />
        </inertial>
        <visual>
            <origin xyz="0 0.5 0" rpy="0 0 0"/>
            <geometry>
                <box size="0.2 1 0.2" />
            </geometry>
            <material name="Cyan">
                <color rgba="0 1.0 1.0 1.0"/>
            </material>
        </visual>
        <collision>
            <origin xyz="0 0.5 0" rpy="0 0 0"/>
            <geometry>
                <box size="0.2 1 0.2" />
            </geometry>
        </collision>
    </link>
    <joint name="Torso_BackLeg" type="revolute">
       <parent link="Torso"/>
       <child  link="BackLeg"/>
       <origin rpy="0 0 0" xyz="0 -0.5 1" />
     <axis xyz="1 0 0"/>
       <limit effort="0.0" lower="-3.14159" upper="3.14159" velocity="0.0"/>
    </joint>
    <link name="BackLeg">
        <inertial>
            <origin xyz="0 -0.5 0" rpy="0 0 0"/>
            <mass value="1" />
            <inertia ixx="100" ixy="0" ixz="0" iyy="100" iyz="0" izz="100" />
        </inertial>
        <visual>
            <origin xyz="0 -0.5 0" rpy="0 0 0"/>
            <geometry>
                <box size="0.2 1 0.2" />
            </geometry>
            <material name="Cyan">
                <color rgba="0 1.0 1.0 1.0"/>
            </material>
        </visual>
        <collision>
            <origin xyz="0 -0.5 0" rpy="0 0 0"/>
            <geometry>
                <box size="0.2 1 0.2" />
            </geometry>
        </collision>
    </link>
    <joint name="Torso_LeftLegFirst" type="revolute">
       <parent link="Torso"/>
       <child  link="LeftLegFirst"/>
       <origin rpy="0 0 0" xyz="-0.5 -0.1 1" />
     <axis xyz="0 1 0"/>
       <limit effort="0.0" lower="-3.14159" upper="3.14159" velocity="0.0"/>
    </joint>
    <link name="LeftLegFirst">
        <inertial>
            <origin xyz="-0.5 -0.3 0" rpy="0 0 0"/>
            <mass value="1" />
            <inertia ixx="100" ixy="0" ixz="0" iyy="100" iyz="0" izz="100" />
        </inertial>
        <visual>
            <origin xyz="-0.5 -0.3 0" rpy="0 0 0"/>
            <geometry>
                <box size="1.0 0.2 0.2" />
            </geometry>
            <material name="Cyan">
                <color rgba="0 1.0 1.0 1.0"/>
            </material>
        </visual>
        <collision>
            <origin xyz="-0.5 -0.3 0" rpy="0 0 0"/>
            <geometry>
                <box size="1.0 0.2 0.2" />
            </geometry>
        </collision>
    </link>
    <joint name="Torso_LeftLegSecond" type="revolute">
       <parent link="Torso"/>
       <child  link="LeftLegSecond"/>
       <origin rpy="0 0 0" xyz="-0.5 0.1 1" />
     <axis xyz="0 1 0"/>
       <limit effort="0.0" lower="-3.14159" upper="3.14159" velocity="0.0"/>
    </joint>
    <link name="LeftLegSecond">
        <inertial>
            <origin xyz="-0.5 0.3 0" rpy="0 0 0"/>
            <mass value="1" />
            <inertia ixx="100" ixy="0" ixz="0" iyy="100" iyz="0" izz="100" />
        </inertial>
        <visual>
            <origin xyz="-0.5 0.3 0" rpy="0 0 0"/>
            <geometry>
                <box size="1.0 0.2 0.2" />
            </geometry>
            <material name="Cyan">
                <color rgba="0 1.0 1.0 1.0"/>
            </material>
        </visual>
        <collision>
            <origin xyz="-0.5 0.3 0" rpy="0 0 0"/>
            <geometry>
                <box size="1.0 0.2 0.2" />
            </geometry>
        </collision>
    </link>
    <joint name="Torso_RightLegFirst" type="revolute">
       <parent link="Torso"/>
       <child  link="RightLegFirst"/>
       <origin rpy="0 0 0" xyz="0.5 -0.1 1" />
     <axis xyz="0 1 0"/>
       <limit effort="0.0" lower="-3.14159" upper="3.14159" velocity="0.0"/>
    </joint>
    <link name="RightLegFirst">
        <inertial>
            <origin xyz="0.5 -0.3 0" rpy="0 0 0"/>
            <mass value="1" />
            <inertia ixx="100" ixy="0" ixz="0" iyy="100" iyz="0" izz="100" />
        </inertial>
        <visual>
            <origin xyz="0.5 -0.3 0" rpy="0 0 0"/>
            <geometry>
                <box size="1.0 0.2 0.2" />
            </geometry>
            <material name="Cyan">
                <color rgba="0 1.0 1.0 1.0"/>
            </material>
        </visual>
        <collision>
            <origin xyz="0.5 -0.3 0" rpy="0 0 0"/>
            <geometry>
                <box size="1.0 0.2 0.2" />
            </geometry>
        </collision>
    </link>
    <joint name="Torso_RightLegSecond" type="revolute">
       <parent link="Torso"/>
       <child  link="RightLegSecond"/>
       <origin rpy="0 0 0" xyz="0.5 0.1 1" />
     <axis xyz="0 1 0"/>
       <limit effort="0.0" lower="-3.14159" upper="3.14159" velocity="0.0"/>
    </joint>
    <link name="RightLegSecond">
        <inertial>
            <origin xyz="0.5 0.3 0" rpy="0 0 0"/>
            <mass value="1" />
            <inertia ixx="100" ixy="0" ixz="0" iyy="100" iyz="0" izz="100" />
        </inertial>
        <visual>
            <origin xyz="0.5 0.3 0" rpy="0 0 0"/>
            <geometry>
                <box size="1.0 0.2 0.2" />
            </geometry>
            <material name="Cyan">
                <color rgba="0 1.0 1.0 1.0"/>
            </material>
        </visual>
        <collision>
            <origin xyz="0.5 0.3 0" rpy="0 0 0"/>
            <geometry>
                <box size="1.0 0.2 0.2" />
            </geometry>
        </collision>
    </link>
    <joint name="FrontLeg_FrontLowerLeg" type="revolute">
       <parent link="FrontLeg"/>
       <child  link="FrontLowerLeg"/>
       <origin rpy="0 0 0" xyz="0 1 0" />
     <axis xyz="1 0 0"/>
       <limit effort="0.0" lower="-3.14159" upper="3.14159" velocity="0.0"/>
    </joint>
    <link name="FrontLowerLeg">
        <inertial>
            <origin xyz="0 0 -0.5" rpy="0 0 0"/>
            <mass value="1" />
            <inertia ixx="100" ixy="0" ixz="0" iyy="100" iyz="0" izz="100" />
        </inertial>
        <visual>
            <origin xyz="0 0 -0.5" rpy="0 0 0"/>
            <geometry>
                <box size="0.2 0.2 1" />
            </geometry>
            <material name="Cyan">
                <color rgba="0 1.0 1.0 1.0"/>
            </material>
        </visual>
        <collision>
            <origin xyz="0 0 -0.5" rpy="0 0 0"/>
            <geometry>
                <box size="0.2 0.2 1" />
            </geometry>
        </collision>
    </link>
    <joint name="BackLeg_BackLowerLeg" type="revolute">
       <parent link="BackLeg"/>
       <child  link="BackLowerLeg"/>
       <origin rpy="0 0 0" xyz="0 -1 0" />
     <axis xyz="1 0 0"/>
       <limit effort="0.0" lower="-3.14159" upper="3.14159" velocity="0.0"/>
    </joint>
    <link name="BackLowerLeg">
        <inertial>
            <origin xyz="0 0 -0.5" rpy="0 0 0"/>
            <mass value="1" />
            <inertia ixx="100" ixy="0" ixz="0" iyy="100" iyz="0" izz="100" />
        </inertial>
        <visual>
            <origin xyz="0 0 -0.5" rpy="0 0 0"/>
            <geometry>
                <box size="0.2 0.2 1" />
            </geometry>
            <material name="Cyan">
                <color rgba="0 1.0 1.0 1.0"/>
            </material>
        </visual>
        <collision>
            <origin xyz="0 0 -0.5" rpy="0 0 0"/>
            <geometry>
                <box size="0.2 0.2 1" />
            </geometry>
        </collision>
    </link>
    <joint name="LeftLegFirst_LeftLowerLegFirst" type="revolute">
       <parent link="LeftLegFirst"/>
       <child  link="LeftLowerLegFirst"/>
       <origin rpy="0 0 0" xyz="-1 0 0" />
     <axis xyz="0 1 0"/>
       <limit effort="0.0" lower="-3.14159" upper="3.14159" velocity="0.0"/>
    </joint>
    <link name="LeftLowerLegFirst">
        <inertial>
            <origin xyz="0 -0.3 -0.5" rpy="0 0 0"/>
            <mass value="1" />
            <inertia ixx="100" ixy="0" ixz="0" iyy="100" iyz="0" izz="100" />
        </inertial>
        <visual>
            <origin xyz="0 -0.3 -0.5" rpy="0 0 0"/>
            <geometry>
                <box size="0.2 0.2 1" />
            </geometry>
            <material name="Cyan">
                <color rgba="0 1.0 1.0 1.0"/>
            </material>
        </visual>
        <collision>
            <origin xyz="0 -0.3 -0.5" rpy="0 0 0"/>
            <geometry>
                <box size="0.2 0.2 1" />
            </geometry>
        </collision>
    </link>
    <joint name="LeftLegSecond_LeftLowerLegSecond" type="revolute">
       <parent link="LeftLegSecond"/>
       <child  link="LeftLowerLegSecond"/>
       <origin rpy="0 0 0" xyz="-1 0 0" />
     <axis xyz="0 1 0"/>
       <limit effort="0.0" lower="-3.14159" upper="3.14159" velocity="0.0"/>
    </joint>
    <link name="LeftLowerLegSecond">
        <inertial>
            <origin xyz="0 0.3 -0.5" rpy="0 0 0"/>
            <mass value="1" />
            <inertia ixx="100" ixy="0" ixz="0" iyy="100" iyz="0" izz="100" />
        </inertial>
        <visual>
            <origin xyz="0 0.3 -0.5" rpy="0 0 0"/>
            <geometry>
                <box size="0.2 0.2 1" />
            </geometry>
            <material name="Cyan">
                <color rgba="0 1.0 1.0 1.0"/>
            </material>
        </visual>
        <collision>
            <origin xyz="0 0.3 -0.5" rpy="0 0 0"/>
            <geometry>
                <box size="0.2 0.2 1" />
            </geometry>
        </collision>
    </link>
    <joint name="RightLegFirst_RightLowerLegFirst" type="revolute">
       <parent link="RightLegFirst"/>
       <child  link="RightLowerLegFirst"/>
       <origin rpy="0 0 0" xyz="1 0 0" />
     <axis xyz="0 1 0"/>
       <limit effort="0.0" lower="-3.14159" upper="3.14159" velocity="0.0"/>
    </joint>
    <link name="RightLowerLegFirst">
        <inertial>
            <origin xyz="0 -0.3 -0.5" rpy="0 0 0"/>
            <mass value="1" />
            <inertia ixx="100" ixy="0" ixz="0" iyy="100" iyz="0" izz="100" />
        </inertial>
        <visual>
            <origin xyz="0 -0.3 -0.5" rpy="0 0 0"/>
            <geometry>
                <box size="0.2 0.2 1" />
            </geometry>
            <material name="Cyan">
                <color rgba="0 1.0 1.0 1.0"/>
            </material>
        </visual>
        <collision>
            <origin xyz="0 -0.3 -0.5" rpy="0 0 0"/>
            <geometry>
                <box size="0.2 0.2 1" />
            </geometry>
        </collision>
    </link>
    <joint name="RightLegSecond_RightLowerLegSecond" type="revolute">
       <parent link="RightLegSecond"/>
       <child  link="RightLowerLegSecond"/>
       <origin rpy="0 0 0" xyz="1 0 0" />
     <axis xyz="0 1 0"/>
       <limit effort="0.0" lower="-3.14159" upper="3.14159" velocity="0.0"/>
    </joint>
    <link name="RightLowerLegSecond">
        <inertial>
            <origin xyz="0 0.3 -0.5" rpy="0 0 0"/>
            <mass value="1" />
            <inertia ixx="100" ixy="0" ixz="0" iyy="100" iyz="0" izz="100" />
        </inertial>
        <visual>
            <origin xyz="0 0.3 -0.5" rpy="0 0 0"/>
            <geometry>
                <box size="0.2 0.2 1" />
            </geometry>
            <material name="Cyan">
                <color rgba="0 1.0 1.0 1.0"/>
            </material>
        </visual>
        <collision>
            <origin xyz="0 0.3 -0.5" rpy="0 0 0"/>
            <geometry>
                <box size="0.2 0.2 1" />
            </geometry>
        </collision>
    </link>
</robot>